Workbook

Sheet COT
F1: Calle seis Mz. D lote 13
F2: Urb. Industrial Grimaneza, Callao
F3: postmaster@bbti.com.pe
F4: www.bbti.com.pe
B6: BBTI S.A.C | D6: FABRICANTES DE TABLEROS ELECTRICOS | E6: CALIDAD Y GARANTIA
B7: 20565747356
F9: Callao, 13 de marzo del 2026
B11: COTIZACION: BB - 046- 25 Rev.2
B13: Sres | C13: : | D13: CONSORIO FOTOVOLTAICO ANDOAS
B14: R.U.C. | C14: : | D14: 20510413301
B15: Atencion | C15: : | D15: HENRY LOZANO
B16: Ref | C16: : | D16: 946-928-450
B17: Asunto | C17: : | D17: COTIZACION DE TABLEROS ELECTRICOS PARA LA OBRA: “AMPLIACIÓN DE LA ELECTRIFICACIÓN RURAL EN EL DISTRITO DE ANDOAS, PROVINCIA DATEM DEL MARAÑÓN, REGIÓN LORETO”
B19: Estimados Sres:
B20: En atencion a su grata solicitud, tenemos a bien alcanzarles nuestra propuesta tecnico economica
B22: ITEM | C22: CANT. | D22: DESCRIPCIÓN | E22: P. UNITARIO | F22: P. TOTAL | G22: ESPECIFICACION
E23: S/ | F23: S/ | G23: TECNICA
B24: 1 | D24: CAJAS DE TRANSICION CON ESTRUCTURA DE SOPORTE
B25: =+B24+0.01 -> 1.01 | C25: 8 | D25: CAJA CON SOPORTE 01 STRING 1KV | E25: =+E169 -> 8840.0856 | F25: =ROUND(E25*C25,2) -> 70720.68 | G25: ETS-SFVC - 12
B26: =+B25+0.01 -> 1.02 | C26: 3 | D26: CAJA CON SOPORTE 02 STRING 1KV | E26: =+E185 -> 16892.448 | F26: =ROUND(E26*C26,2) -> 50677.34 | G26: ETS-SFVC - 12
B27: =+B26+0.01 -> 1.03 | C27: 5 | D27: CAJA CON SOPORTE 03 STRING 1KV | E27: =+E201 -> 24944.811 | F27: =ROUND(E27*C27,2) -> 124724.05 | G27: ETS-SFVC - 12
B28: =+B27+0.01 -> 1.04 | C28: 23 | D28: CAJA CON SOPORTE 04 STRING 1KV | E28: =+E217 -> 32997.173 | F28: =ROUND(E28*C28,2) -> 758934.98 | G28: ETS-SFVC - 12
B29: =+B28+0.01 -> 1.05 | C29: 8 | D29: CAJA CON SOPORTE 05 STRING 1KV | E29: =+E233 -> 41059.286 | F29: =ROUND(E29*C29,2) -> 328474.28 | G29: ETS-SFVC - 12
B30: =+B29+0.01 -> 1.06 | C30: 5 | D30: CAJA CON SOPORTE 06 STRING 1KV | E30: =+E249 -> 49111.648 | F30: =ROUND(E30*C30,2) -> 245558.24 | G30: ETS-SFVC - 12
B31: =+B30+0.01 -> 1.07 | C31: 3 | D31: CAJA CON SOPORTE 07 STRING 1KV | E31: =+E265 -> 57164.011 | F31: =ROUND(E31*C31,2) -> 171492.03 | G31: ETS-SFVC - 12
B32: 2 | D32: CAJAS DE PARALELAJE CON ESTRUCTURA DE SOPORTE
B33: =+B32+0.01 -> 2.01 | C33: 1 | D33: CAJA PARA ENTRADA DE 04 STRING 1KV EN PARALELAJE PARA SALIDA DE 02 STRINGS 1KV | E33: =ROUND(E282,2) -> 28502.75 | F33: =ROUND(E33*C33,2) -> 28502.75 | G33: ETS-SFVC - 12
B34: =+B33+0.01 -> 2.02 | C34: 1 | D34: CAJA PARA ENTRADA DE 06 STRING 1KV EN PARALELAJE PARA SALIDA DE 02 STRINGS 1KV | E34: =ROUND(E299,2) -> 36542.27 | F34: =ROUND(E34*C34,2) -> 36542.27 | G34: ETS-SFVC - 12
B35: 3 | D35: TABLEROS DE INTERCONEXION DE POTENCIA (GABINETES ELECTRICOS HERMETICO, DE CONTROL PARA LOS INVERSORES)
B36: =+B35+0.01 -> 3.01 | C36: 4 | D36: TABLEROS DE POTENCIA TIPO 01 (incluye aire acondicionado) | E36: =ROUND(E316,2) -> 1225.2 | F36: =ROUND(E36*C36,2) -> 4900.8 | G36: ETS-SFVC - 19
B37: =+B36+0.01 -> 3.02 | C37: 2 | D37: TABLEROS DE POTENCIA TIPO 02 (incluye aire acondicionado) | E37: =ROUND(E345,2) -> 1215.6 | F37: =ROUND(E37*C37,2) -> 2431.2 | G37: ETS-SFVC - 19
B38: =+B37+0.01 -> 3.03 | C38: 1 | D38: TABLEROS DE POTENCIA TIPO 03 (incluye aire acondicionado) | E38: =ROUND(E372,2) -> 1210.8 | F38: =ROUND(E38*C38,2) -> 1210.8 | G38: ETS-SFVC - 19
B39: =+B38+0.01 -> 3.04 | C39: 1 | D39: TABLEROS DE POTENCIA TIPO 04 (incluye aire acondicionado) | E39: =ROUND(E399,2) -> 1220.4 | F39: =ROUND(E39*C39,2) -> 1220.4 | G39: ETS-SFVC - 19
B40: =+B39+0.01 -> 3.05 | C40: 2 | D40: TABLEROS DE POTENCIA TIPO 05 (incluye aire acondicionado) | E40: =ROUND(E426,2) -> 2125.2 | F40: =ROUND(E40*C40,2) -> 4250.4 | G40: ETS-SFVC - 19
B41: =+B40+0.01 -> 3.06 | C41: 3 | D41: TABLEROS DE POTENCIA TIPO 06 (incluye aire acondicionado) | E41: =ROUND(E453,2) -> 1337.3 | F41: =ROUND(E41*C41,2) -> 4011.9 | G41: ETS-SFVC - 19
B42: =+B41+0.01 -> 3.07 | C42: 3 | D42: TABLEROS DE POTENCIA TIPO 07 (incluye aire acondicionado) | E42: =ROUND(E477,2) -> 2576.26 | F42: =ROUND(E42*C42,2) -> 7728.78 | G42: ETS-SFVC - 19
B43: =+B42+0.01 -> 3.08 | C43: 1 | D43: TABLEROS DE POTENCIA TIPO 08 (incluye aire acondicionado) | E43: =ROUND(E502,2) -> 2146.8 | F43: =ROUND(E43*C43,2) -> 2146.8 | G43: ETS-SFVC - 19
B44: =+B43+0.01 -> 3.09 | C44: 3 | D44: TABLEROS DE POTENCIA TIPO 09 (incluye aire acondicionado) | E44: =ROUND(E530,2) -> 3139.2 | F44: =ROUND(E44*C44,2) -> 9417.6 | G44: ETS-SFVC - 19
B45: =+B44+0.01 -> 3.1 | C45: 1 | D45: TABLEROS DE POTENCIA TIPO 09.1 (incluye aire acondicionado) | E45: =+E530 -> 3139.2 | F45: =ROUND(E45*C45,2) -> 3139.2 | G45: ETS-SFVC - 19
B46: =+B45+0.01 -> 3.11 | C46: 2 | D46: TABLEROS DE POTENCIA TIPO 10 (incluye aire acondicionado) | E46: =ROUND(E587,2) -> 4165.2 | F46: =ROUND(E46*C46,2) -> 8330.4 | G46: ETS-SFVC - 19
...

Sheet Precios Equipos
B2: RESUMEN DE COSTOS (EQUIPOS, BARRAS, GABINETE, M. OBRA)
F4: T. Cambio | G4: 3.4
F5: Incremento ABB | G5: 1.13
F6: Dscto. ABB | G6: 0.52
E7: AIRE ACONDICIONADO | F7: Desaduanaje | G7: 1.5
F8: Aumento | G8: 2
B10: ITEM | C10: DESCRIPCION (EQUIPOS) | D10: CODIGO | E10: UND | F10: P.UNIT | G10: P.TOTAL
C11: INTERRUPTORES CAJA MOLDEADA CORRIENTE ALTERNA
B12: 1 | C12: ITM 2x16A, Caja Moldeada, 50kA en 220VAC, A1N, ABB | E12: =SUMIFS(COT!$Q$168:$Q$2789,COT!$D$168:$D$2789,'Precios Equipos'!C12) -> 20 | F12: 117 | G12: =+F12*E12 -> 2340 | N12: =+K12-E12 -> -20
B13: =+B12+1 -> 2 | C13: ITM 2x20A, Caja Moldeada, 50kA en 220VAC, A1N, ABB | E13: =SUMIFS(COT!$Q$168:$Q$2789,COT!$D$168:$D$2789,'Precios Equipos'!C13) -> 8 | F13: 117 | G13: =+F13*E13 -> 936 | N13: =+K13-E13 -> -8
B14: =+B13+1 -> 3 | C14: ITM 2x25A, Caja Moldeada, 50kA en 220VAC, A1N, ABB | E14: =SUMIFS(COT!$Q$168:$Q$2789,COT!$D$168:$D$2789,'Precios Equipos'!C14) -> 110 | F14: 123 | G14: =+F14*E14 -> 13530 | N14: =+K14-E14 -> -110
B15: =+B14+1 -> 4 | C15: ITM 2x32A, Caja Moldeada, 50kA en 220VAC, A1N, ABB | E15: =SUMIFS(COT!$Q$168:$Q$2789,COT!$D$168:$D$2789,'Precios Equipos'!C15) -> 88 | F15: 117 | G15: =+F15*E15 -> 10296 | N15: =+K15-E15 -> -88
B16: =+B15+1 -> 5 | C16: ITM 2x50A, Caja Moldeada, 50kA en 220VAC, A1N, ABB | E16: =SUMIFS(COT!$Q$168:$Q$2789,COT!$D$168:$D$2789,'Precios Equipos'!C16) -> 36 | F16: 145 | G16: =+F16*E16 -> 5220 | N16: =+K16-E16 -> -36
B17: =+B16+1 -> 6 | C17: ITM 2x63A, Caja Moldeada, 50kA en 220VAC, A1N, ABB | E17: =SUMIFS(COT!$Q$168:$Q$2789,COT!$D$168:$D$2789,'Precios Equipos'!C17) -> 9 | F17: 159 | G17: =+F17*E17 -> 1431 | N17: =+K17-E17 -> -9
B18: =+B17+1 -> 7 | C18: ITM 2x100A, Caja Moldeada 100A, 50kA en 220VAC, A1N/P, ABB | E18: =SUMIFS(COT!$Q$168:$Q$2789,COT!$D$168:$D$2789,'Precios Equipos'!C18) -> 138 | F18: 132 | G18: =+F18*E18 -> 18216 | N18: =+K18-E18 -> -138
B19: =+B18+1 -> 8 | C19: ITM 3x25A, Caja Moldeada (17.5-25)A, 25kA en 380VAC, XT1C, ABB | E19: =SUMIFS(COT!$Q$168:$Q$2789,COT!$D$168:$D$2789,'Precios Equipos'!C19) -> 8 | F19: 246 | G19: =+F19*E19 -> 1968 | N19: =+K19-E19 -> -8
B20: =+B19+1 -> 9 | C20: ITM 3x32A, Caja Moldeada (22.4-32)A, 25kA en 380VAC, XT1C, ABB | E20: =SUMIFS(COT!$Q$168:$Q$2789,COT!$D$168:$D$2789,'Precios Equipos'!C20) -> 16 | F20: 246 | G20: =+F20*E20 -> 3936 | N20: =+K20-E20 -> -16
B21: =+B20+1 -> 10 | C21: ITM 3x50A, Caja Moldeada (35-50)A, 25kA en 380VAC, XT1C, ABB | E21: =SUMIFS(COT!$Q$168:$Q$2789,COT!$D$168:$D$2789,'Precios Equipos'!C21) -> 41 | F21: 246 | G21: =+F21*E21 -> 10086 | N21: =+K21-E21 -> -41
B22: =+B21+1 -> 11 | C22: ITM 3x80A, Caja Moldeada (56-80)A, 25kA en 380VAC, XT1C, ABB | E22: =SUMIFS(COT!$Q$168:$Q$2789,COT!$D$168:$D$2789,'Precios Equipos'!C22) -> 2 | F22: 255 | G22: =+F22*E22 -> 510 | N22: =+K22-E22 -> -2
B23: =+B22+1 -> 12 | C23: ITM 4x100A, Caja Moldeada (70-100)A, 36kA en 380VAC, XT1, ABB | E23: =SUMIFS(COT!$Q$168:$Q$2789,COT!$D$168:$D$2789,'Precios Equipos'!C23) -> 12 | F23: =1234*G5*G6*1.35 -> 978.88284 | G23: =+F23*E23 -> 11746.594 | N23: =+K23-E23 -> -12
B24: =+B23+1 -> 13 | C24: ITM 4x100A, Caja Moldeada (70-100)A, 25kA en 380VAC, XT1C, ABB | E24: =SUMIFS(COT!$Q$168:$Q$2789,COT!$D$168:$D$2789,'Precios Equipos'!C24) -> 12 | F24: 382 | G24: =+F24*E24 -> 4584 | N24: =+K24-E24 -> -12
B25: =+B24+1 -> 14 | C25: ITM 3x800A, Caja Moldeada (320-800)A, 36kA en 380VAC, XT6N, ABB | E25: =SUMIFS(COT!$Q$168:$Q$2789,COT!$D$168:$D$2789,'Precios Equipos'!C25) -> 1 | F25: 4140 | G25: =+F25*E25 -> 4140 | N25: =+K25-E25 -> -1
B26: =+B25+1 -> 15 | C26: ITM 2 x 16A, Caja Moldeada, 15KA@440V, 2B160, SIGMA ELEKTRIK | E26: =SUMIFS(COT!$Q$168:$Q$2789,COT!$D$168:$D$2789,'Precios Equipos'!C26) -> 115 | F26: 232.96 | G26: =+F26*E26 -> 26790.4 | N26: =+K26-E26 -> -115
B27: =+B26+1 -> 16 | C27: ITM 2 x 25A, Caja Moldeada, 15KA@440V, 2B160, SIGMA ELEKTRIK | E27: =SUMIFS(COT!$Q$168:$Q$2789,COT!$D$168:$D$2789,'Precios Equipos'!C27) -> 91 | F27: 232.96 | G27: =+F27*E27 -> 21199.36 | N27: =+K27-E27 -> -91
B28: =+B27+1 -> 17 | C28: ITM 2 x 40A, Caja Moldeada, 15KA@440V, 2B160, SIGMA ELEKTRIK | E28: =SUMIFS(COT!$Q$168:$Q$2789,COT!$D$168:$D$2789,'Precios Equipos'!C28) -> 61 | F28: 232.96 | G28: =+F28*E28 -> 14210.56 | N28: =+K28-E28 -> -61
B29: =+B28+1 -> 18 | C29: ITM 2 x 63A, Caja Moldeada, 15KA@440V, 2B160, SIGMA ELEKTRIK | E29: =SUMIFS(COT!$Q$168:$Q$2789,COT!$D$168:$D$2789,'Precios Equipos'!C29) -> 20 | F29: 250.64 | G29: =+F29*E29 -> 5012.8 | N29: =+K29-E29 -> -20
B30: =+B29+1 -> 19 | C30: ITM 3 x 25A, Caja Moldeada, Reg. (20-25)A, 25KA@380V, 3B160, SIGMA ELEKTRIK | E30: =SUMIFS(COT!$Q$168:$Q$2789,COT!$D$168:$D$2789,'Precios Equipos'!C30) -> 1 | F30: 190 | G30: =+F30*E30 -> 190 | N30: =+K30-E30 -> -1
B31: =+B30+1 -> 20 | C31: ITM 3 x 40A, Caja Moldeada, Reg. (32-40)A, 25KA@380V, 3B160, SIGMA ELEKTRIK | E31: =SUMIFS(COT!$Q$168:$Q$2789,COT!$D$168:$D$2789,'Precios Equipos'!C31) -> 5 | F31: 190 | G31: =+F31*E31 -> 950 | N31: =+K31-E31 -> -5
B32: =+B31+1 -> 21 | C32: ITM 3 x 63A, Caja Moldeada, Reg. (50.4-63)A, 25KA@380V, 3B160, SIGMA ELEKTRIK | E32: =SUMIFS(COT!$Q$168:$Q$2789,COT!$D$168:$D$2789,'Precios Equipos'!C32) -> 1 | F32: 190 | G32: =+F32*E32 -> 190 | N32: =+K32-E32 -> -1
C33: MEDIDORES | N33: =+K33-E33 -> 0
B34: =+B32+1 -> 22 | C34: Medidor Electronico HXE34KS-1, HEXING | E34: =SUMIFS(COT!$Q$168:$Q$2789,COT!$D$168:$D$2789,'Precios Equipos'!C34) -> 42 | F34: 190 | G34: =+F34*E34 -> 7980 | N34: =+K34-E34 -> -42
B35: =+B34+1 -> 23 | C35: Medidor Electronico Monofasico HXE12ES, HEXING | E35: =SUMIFS(COT!$Q$168:$Q$2789,COT!$D$168:$D$2789,'Precios Equipos'!C35) -> 41 | F35: 41.8 | G35: =+F35*E35 -> 1713.8 | N35: =+K35-E35 -> -41
B36: =+B35+1 -> 24 | C36: Medidor Electronico Polifasico HXF300, HEXING | E36: =SUMIFS(COT!$Q$168:$Q$2789,COT!$D$168:$D$2789,'Precios Equipos'!C36) -> 1 | F36: 1824 | G36: =+F36*E36 -> 1824 | N36: =+K36-E36 -> -1
B37: =+B36+1 -> 25 | C37: Medidor Multifuncion comunicación M1M 15 Modbus RTU ABB | E37: =SUMIFS(COT!$Q$168:$Q$2789,COT!$D$168:$D$2789,'Precios Equipos'!C37) -> 0 | F37: 662.81 | G37: =+F37*E37 -> 0 | N37: =+K37-E37 -> 0
C38: INTERRUPTORES CAJA MOLDEADA CORRIENTE CONTINUA | N38: =+K38-E38 -> 0
B39: =+B37+1 -> 26 | C39: ITM 2x40A, Caja Moldeada, 50kA en 220V, A1N, ABB, DC | E39: =SUMIFS(COT!$Q$168:$Q$2789,COT!$D$168:$D$2789,'Precios Equipos'!C39) -> 2 | F39: 123 | G39: =+F39*E39 -> 246 | N39: =+K39-E39 -> -2
B40: =+B39+1 -> 27 | C40: ITM 2x50A, Caja Moldeada, 50kA en 220V, A1N, ABB, DC | E40: =SUMIFS(COT!$Q$168:$Q$2789,COT!$D$168:$D$2789,'Precios Equipos'!C40) -> 9 | F40: 123 | G40: =+F40*E40 -> 1107 | N40: =+K40-E40 -> -9
B41: =+B40+1 -> 28 | C41: ITM 2x63A, Caja Moldeada 63A, 50kA en 220V, A1N/P, ABB, DC | E41: =SUMIFS(COT!$Q$168:$Q$2789,COT!$D$168:$D$2789,'Precios Equipos'!C41) -> 24 | F41: 132 | G41: =+F41*E41 -> 3168 | N41: =+K41-E41 -> -24
B42: =+B41+1 -> 29 | C42: ITM 2x125A, Caja Moldeada 125A, 25kA en 220V, A1N/P, ABB, DC | E42: =SUMIFS(COT!$Q$168:$Q$2789,COT!$D$168:$D$2789,'Precios Equipos'!C42) -> 78 | F42: 330 | G42: =+F42*E42 -> 25740 | N42: =+K42-E42 -> -78
B43: =+B42+1 -> 30 | C43: ITM 2x160A, Caja Moldeada 160A, 50kA en 220V, A2N 250, ABB, DC | E43: =SUMIFS(COT!$Q$168:$Q$2789,COT!$D$168:$D$2789,'Precios Equipos'!C43) -> 92 | F43: 405 | G43: =+F43*E43 -> 37260 | N43: =+K43-E43 -> -92
...

Sheet Materiales
B2: COSTO DE MANO DE OBRA
C4: ITEM | D4: MANO DE OBRA ELECTRICIDAD INTERRUPTORES | E4: PRECIO (S/) | F4: CANTIDAD | G4: SUB TOTAL
B5: ELECTRICIDAD ITM | C5: 1 | D5: Mano de obra 6-10 polos (3-5 ITM) | E5: =70*0.75 -> 52.5 | F5: ='Precios Equipos'!E140 -> 17 | G5: =F5*E5 -> 892.5
C6: 2 | D6: Mano de obra 12-16 polos (6-8 ITM) | E6: =100*0.75 -> 75 | F6: ='Precios Equipos'!E141 -> 16 | G6: =F6*E6 -> 1200
C7: 3 | D7: Mano de obra 18-22 polos (9-11 ITM) | E7: =120*0.75 -> 90 | F7: 0 | G7: =F7*E7 -> 0
C8: 4 | D8: Mano de obra 24-28 polos (12-16 ITM) | E8: =140*0.75 -> 105 | F8: ='Precios Equipos'!#REF! -> #REF! | G8: =F8*E8 -> #REF!
C9: 5 | D9: Mano de obra 30-34 polos (18-22 ITM) | E9: =160*0.75 -> 120 | F9: ='Precios Equipos'!#REF! -> #REF! | G9: =F9*E9 -> #REF!
G10: =SUM(G5:G9) -> #REF!
C12: ITEM | D12: MANO DE OBRA ELECTRICIDAD DIFERENCIALES | E12: PRECIO (S/) | F12: CANTIDAD | G12: SUB TOTAL
C13: 6 | D13: Mano de obra 1-2 Diferenciales | E13: =20*0.75 -> 15 | F13: ='Precios Equipos'!#REF! -> #REF! | G13: =F13*E13 -> #REF!
B14: ELECTRICIDAD DIFERENCIALE | C14: 6 | D14: Mano de obra 3-5 Diferenciales | E14: =40*0.75 -> 30 | F14: ='Precios Equipos'!#REF! -> #REF! | G14: =F14*E14 -> #REF!
C15: 7 | D15: Mano de obra 6-8 Diferenciales | E15: =60*0.75 -> 45 | F15: ='Precios Equipos'!#REF! -> #REF! | G15: =F15*E15 -> #REF!
C16: 8 | D16: Mano de obra 9-11 Diferenciales | E16: =80*0.75 -> 60 | F16: 0 | G16: =F16*E16 -> 0
C17: 9 | D17: Mano de obra 12-16 Diferenciales | E17: =100*0.75 -> 75 | F17: ='Precios Equipos'!#REF! -> #REF! | G17: =F17*E17 -> #REF!
C18: 10 | D18: Mano de obra 18-22 Diferenciales | E18: =120*0.75 -> 90 | F18: ='Precios Equipos'!#REF! -> #REF! | G18: =F18*E18 -> #REF!
G19: =SUM(G14:G18) -> #REF!
C21: ITEM | D21: MANO DE OBRA ELECTRICIDAD AUTOSOPORTADO | E21: PRECIO (S/) | F21: CANTIDAD | G21: SUB TOTAL
B22: ELECTRICIDAD AUTOSOPORTADO | C22: 11 | D22: Mano de obra Autosoportado ITEM 2 | E22: 1000 | F22: 1 | G22: =F22*E22 -> 1000
C23: 11 | D23: Mano de obra Autosoportado ITEM PARA TIPO 1 AL TIPO 4.2 | E23: 1000 | F23: 1 | G23: =F23*E23 -> 1000
C24: 11 | D24: Mano de obra Autosoportado TTA-1 | E24: 1500 | F24: 1 | G24: =F24*E24 -> 1500
C25: 11 | D25: Mano de obra Autosoportado 800A | E25: 700 | F25: 1 | G25: =F25*E25 -> 700
C26: 11 | D26: Mano de obra Autosoportado TGE | E26: 1000 | F26: 1 | G26: =F26*E26 -> 1000
C27: 11 | D27: Mano de obra Autosoportado TGES.EI | E27: 350 | F27: 1 | G27: =F27*E27 -> 350
C28: 11 | D28: Mano de obra Autosoportado TBCI | E28: 350 | F28: 1 | G28: =F28*E28 -> 350
C29: 12 | D29: Mano de obra Autosoportado TGN-1 | E29: 600 | F29: 1 | G29: =F29*E29 -> 600
C30: 13 | D30: Mano de obra Autosoportado TGE-1 | E30: 500 | F30: 1 | G30: =F30*E30 -> 500
C31: 14 | D31: Mano de obra Autosoportado TGES-1 | E31: 450 | F31: 1 | G31: =F31*E31 -> 450
G32: =SUM(G22:G31) -> 7450
C35: ITEM | D35: MANO DE OBRA GABINETE EMPOTRADO | E35: PRECIO (S/) | F35: CANTIDAD | G35: SUB TOTAL
B36: EMPOTRADO | C36: 15 | D36: M. Obra Empotrado 700x450x150mm (Mecanica, Soldadura, Pintura, Armado) | E36: =40*4*0.75 -> 120 | F36: 6 | G36: =F36*E36 -> 720
C37: 16 | D37: M. Obra Empotrado 800x450x150mm (Mecanica, Soldadura, Pintura, Armado) | E37: =50*4*0.75 -> 150 | F37: 29 | G37: =F37*E37 -> 4350
C38: 16 | D38: M. Obra Empotrado 900x450x150mm (Mecanica, Soldadura, Pintura, Armado) | E38: =250*0.75 -> 187.5 | F38: 29 | G38: =F38*E38 -> 5437.5
C39: 17 | D39: M. Obra Empotrado 1000x600x150mm (Mecanica, Soldadura, Pintura, Armado) | E39: =75*4*0.75 -> 225 | F39: 19 | G39: =F39*E39 -> 4275
C40: 18 | D40: M. Obra Empotrado 1100x600x150mm (Mecanica, Soldadura, Pintura, Armado) | E40: =350*0.75 -> 262.5 | F40: 0 | G40: =F40*E40 -> 0
C41: 19 | D41: M. Obra Empotrado 1200x600x150mm (Mecanica, Soldadura, Pintura, Armado) | E41: =400*0.75 -> 300 | F41: ='Precios Equipos'!#REF! -> #REF! | G41: =F41*E41 -> #REF!
C42: 19 | D42: M. Obra Empotrado 1400x600x150mm (Mecanica, Soldadura, Pintura, Armado) | E42: =500*0.75 -> 375 | F42: ='Precios Equipos'!#REF! -> #REF! | G42: =F42*E42 -> #REF!
G43: =SUM(G36:G41) -> #REF!
C45: ITEM | D45: MANO DE OBRA GABINETE ADOSADO | E45: PRECIO (S/) | F45: CANTIDAD | G45: SUB TOTAL
B46: ADOSADO | C46: 20 | D46: M. Obra Adosado 700x450x150mm (Mecanica, Soldadura, Pintura, Armado) | E46: =40*4*0.75 -> 120 | F46: 0 | G46: =F46*E46 -> 0
C47: 21 | D47: M. Obra Adosado 800x450x150mm (Mecanica, Soldadura, Pintura, Armado) | E47: =50*4*0.75 -> 150 | F47: 0 | G47: =F47*E47 -> 0
...

Sheet Cobre por polos
B2: COSTO SISTEMA DE BARRAS POR NUMERO DE POLOS
B4: ITEM | C4: SISTEMA DE BARRAS 06-08 POLOS | D4: UNIDAD | E4: CANTIDAD | F4: PRECIO S/ | G4: SUB TOTAL S/
B5: 06-08 POLOS | C5: =Materiales!D96 -> Panel de barras de cobre 06-08 polos, R, S, T, Princ. 3x20mm/Derivac. 2x10mm. | D5: Jgo | E5: 1 | F5: =Materiales!G96 -> 93.220339 | G5: =E5*F5 -> 93.220339
C6: Suples 3x20mm | D6: m | E6: =0.2*3 -> 0.6 | F6: 25.55625 | G6: =E6*F6 -> 15.33375
C7: Barra de cobre de 3x20x1mt | D7: Tierra | E7: =0.2 -> 0.2 | F7: 25.55625 | G7: =E7*F7 -> 5.11125
C8: Kits de pernos en general 08-14 polos | D8: Jgo | E8: 1 | F8: 10 | G8: =E8*F8 -> 10
C9: SISTEMA DE BARRAS 08-10 POLOS | G9: =SUM(G5:G8) -> 123.66534
B11: ITEM | C11: SISTEMA DE BARRAS 10-12 POLOS | D11: UNIDAD | E11: CANTIDAD | F11: PRECIO S/ | G11: SUB TOTAL S/
B12: 10-12 POLOS | C12: Panel de barras de cobre 10-12 polos, R, S, T, Princ. 3x20mm/Derivac. 2x10mm. | D12: Jgo | E12: 1 | F12: 110.16949 | G12: =E12*F12 -> 110.16949
C13: Suples 3x20mm | D13: m | E13: =0.2*3 -> 0.6 | F13: 25.55625 | G13: =E13*F13 -> 15.33375
C14: Barra de cobre de 3x20x1mt | D14: Tierra | E14: =0.2 -> 0.2 | F14: 25.55625 | G14: =E14*F14 -> 5.11125
C15: Kits de pernos en general 08-14 polos | D15: Jgo | E15: 1 | F15: 10 | G15: =E15*F15 -> 10
C16: =C11 -> SISTEMA DE BARRAS 10-12 POLOS | G16: =SUM(G12:G15) -> 140.61449
B18: ITEM | C18: SISTEMA DE BARRAS 14-16 POLOS | D18: UNIDAD | E18: CANTIDAD | F18: PRECIO S/ | G18: SUB TOTAL S/
B19: 14-16 POLOS | C19: Panel de barras de cobre 14-16 polos, R, S, T, Princ. 3x20mm/Derivac. 2x10mm. | D19: Jgo | E19: 1 | F19: 127.11864 | G19: =E19*F19 -> 127.11864
C20: Suples 3x20mm | D20: m | E20: =0.2*3 -> 0.6 | F20: 25.55625 | G20: =E20*F20 -> 15.33375
C21: Barra de cobre de 3x20x1mt | D21: Tierra | E21: =0.2 -> 0.2 | F21: 25.55625 | G21: =E21*F21 -> 5.11125
C22: Kits de pernos en general 08-14 polos | D22: Jgo | E22: 1 | F22: 10 | G22: =E22*F22 -> 10
C23: SISTEMA DE BARRAS 14-16 POLOS | G23: =SUM(G19:G22) -> 157.56364
B25: ITEM | C25: SISTEMA DE BARRAS 18-20 POLOS | D25: UNIDAD | E25: CANTIDAD | F25: PRECIO S/ | G25: SUB TOTAL S/
B26: 18-20 POLOS | C26: Panel de barras de cobre 18-20 polos, R, S, T, Princ. 3x20mm/Derivac. 2x10mm. | D26: Jgo | E26: 1 | F26: 144.0678 | G26: =E26*F26 -> 144.0678
C27: Suples 3x20mm | D27: m | E27: =0.2*3 -> 0.6 | F27: 25.55625 | G27: =E27*F27 -> 15.33375
C28: Barra de cobre de 3x20x1mt | D28: Tierra | E28: =0.2 -> 0.2 | F28: 25.55625 | G28: =E28*F28 -> 5.11125
C29: Kits de pernos en general 16-22 polos | D29: Jgo | E29: 1 | F29: 15 | G29: =E29*F29 -> 15
C30: SISTEMA DE BARRAS 18-20 POLOS | G30: =SUM(G26:G29) -> 179.5128
B32: ITEM | C32: SISTEMA DE BARRAS 22-24 POLOS | D32: UNIDAD | E32: CANTIDAD | F32: PRECIO S/ | G32: SUB TOTAL S/
B33: 22-24 POLOS | C33: Panel de barras de cobre 22-24 polos, R, S, T, Princ. 3x20mm/Derivac. 2x10mm. | D33: Jgo | E33: 1 | F33: 161.01695 | G33: =E33*F33 -> 161.01695
C34: Suples 3x20mm | D34: m | E34: =0.2*3 -> 0.6 | F34: 25.55625 | G34: =E34*F34 -> 15.33375
C35: Barra de cobre de 3x20x1mt | D35: Tierra | E35: =0.2 -> 0.2 | F35: 25.55625 | G35: =E35*F35 -> 5.11125
C36: Kits de pernos en general 16-22 polos | D36: Jgo | E36: 1 | F36: 15 | G36: =E36*F36 -> 15
C37: SISTEMA DE BARRAS 22-24 POLOS | G37: =SUM(G33:G36) -> 196.46195
B39: ITEM | C39: SISTEMA DE BARRAS 26-28 POLOS | D39: UNIDAD | E39: CANTIDAD | F39: PRECIO S/ | G39: SUB TOTAL S/
B40: 26-28 POLOS | C40: Panel de barras de cobre 26-28 polos, R, S, T, Princ. 3x20mm/Derivac. 2x10mm. | D40: Jgo | E40: 1 | F40: 177.9661 | G40: =E40*F40 -> 177.9661
C41: Suples 3x20mm | D41: m | E41: =0.2*3 -> 0.6 | F41: 25.55625 | G41: =E41*F41 -> 15.33375
C42: Barra de cobre de 3x20x1mt | D42: Tierra | E42: =0.2 -> 0.2 | F42: 25.55625 | G42: =E42*F42 -> 5.11125
C43: Kits de pernos en general 24-30 polos | D43: Jgo | E43: 1 | F43: 20 | G43: =E43*F43 -> 20
C44: SISTEMA DE BARRAS 26-28 POLOS | G44: =SUM(G40:G43) -> 218.4111
B46: ITEM | C46: SISTEMA DE BARRAS 30-32 POLOS | D46: UNIDAD | E46: CANTIDAD | F46: PRECIO S/ | G46: SUB TOTAL S/
B47: 30-32 POLOS | C47: Panel de barras de cobre 30-32 polos, R, S, T, Princ. 3x20mm/Derivac. 2x10mm. | D47: Jgo | E47: 1 | F47: 194.91525 | G47: =E47*F47 -> 194.91525
C48: Suples 3x20mm | D48: m | E48: =0.2*3 -> 0.6 | F48: 25.55625 | G48: =E48*F48 -> 15.33375
...

Sheet Cableado
B2: COSTO CABLEADO DE DIFERENCIALES
C4: INGRESAR CANTIDADES DE DIFERENCIALES
C5: Cantidad Diferenciales Bipolar 25A | D5: cant. | E5: 12
C6: Cantidad Diferenciales Bipolar 40A | D6: cant. | E6: 0
C7: Cantidad Diferenciales Tripolar + N 25A | D7: cant. | E7: 0
C8: Cantidad Diferenciales Tripolar + N 40A | D8: cant. | E8: 1
B10: N° POLOS | C10: CABLEADO 2 DIFERENCIALES | D10: UNIDAD | E10: CANTIDAD | F10: PRECIO S/ | G10: SUB TOTAL S/
B11: 2 | C11: =Materiales!D111 -> Cable NH-80, 4mm2, 32A, INDECO | D11: m | E11: =E5*2 -> 24 | F11: =Materiales!G111 -> 2.0762712 | G11: =E11*F11 -> 49.830508
B12: 2 | C12: =Materiales!D112 -> Cable NH-80, 6mm2, 41A, INDECO | D12: m | E12: =E6*2 -> 0 | F12: =Materiales!G112 -> 3.21 | G12: =E12*F12 -> 0
B13: 4 | C13: =Materiales!D111 -> Cable NH-80, 4mm2, 32A, INDECO | D13: m | E13: =E7*2 -> 0 | F13: =Materiales!G111 -> 2.0762712 | G13: =E13*F13 -> 0
B14: 4 | C14: =Materiales!D112 -> Cable NH-80, 6mm2, 41A, INDECO | D14: m | E14: =E8*2 -> 2 | F14: =Materiales!G112 -> 3.21 | G14: =E14*F14 -> 6.42
C15: =Materiales!D129 -> M. Menores (canaletas, terminales, marcadores, contillo, etc) 08-14 polos | D15: Jgo | E15: 1 | F15: =Materiales!G129 -> 15 | G15: =E15*F15 -> 15
C16: =C10 -> CABLEADO 2 DIFERENCIALES | G16: =SUM(G11:G15) -> 71.250508
C18: INGRESAR CANTIDADES DE DIFERENCIALES
C19: Cantidad Diferenciales Bipolar 25A | D19: cant. | E19: 1
C20: Cantidad Diferenciales Bipolar 40A | D20: cant. | E20: 0
C21: Cantidad Diferenciales Tripolar + N 25A | D21: cant. | E21: 0
C22: Cantidad Diferenciales Tripolar + N 40A | D22: cant. | E22: 0
B24: N° POLOS | C24: CABLEADO 3 DIFERENCIALES | D24: UNIDAD | E24: CANTIDAD | F24: PRECIO S/ | G24: SUB TOTAL S/
B25: 2 | C25: =Materiales!D111 -> Cable NH-80, 4mm2, 32A, INDECO | D25: m | E25: =E19*2 -> 2 | F25: =Materiales!G111 -> 2.0762712 | G25: =E25*F25 -> 4.1525424
B26: 2 | C26: =Materiales!D112 -> Cable NH-80, 6mm2, 41A, INDECO | D26: m | E26: =E20*2 -> 0 | F26: =Materiales!G112 -> 3.21 | G26: =E26*F26 -> 0
B27: 4 | C27: =Materiales!D111 -> Cable NH-80, 4mm2, 32A, INDECO | D27: m | E27: =E21*2 -> 0 | F27: =Materiales!G111 -> 2.0762712 | G27: =E27*F27 -> 0
B28: 4 | C28: =Materiales!D112 -> Cable NH-80, 6mm2, 41A, INDECO | D28: m | E28: =E22*2 -> 0 | F28: =Materiales!G112 -> 3.21 | G28: =E28*F28 -> 0
C29: =Materiales!D129 -> M. Menores (canaletas, terminales, marcadores, contillo, etc) 08-14 polos | D29: Jgo | E29: 1 | F29: =Materiales!G129 -> 15 | G29: =E29*F29 -> 15
C30: =C24 -> CABLEADO 3 DIFERENCIALES | G30: =SUM(G25:G29) -> 19.152542
C32: RESUMEN CABLEADO DIFERENCIALES 2 POLOS 25A
C33: DESCRIPCION | D33: AMPERAJE | E33: N° POLOS | F33: CANT. | G33: PRECIO (S/)
B34: 0 | C34: CABLEADO 0 DIFERENCIALES, 2P | D34: 25 | E34: 2 | F34: 0 | G34: 0
B35: 1 | C35: CABLEADO 1 DIFERENCIALES, 2P | D35: 25 | E35: 2 | F35: 1 | G35: 19.15
B36: 2 | C36: CABLEADO 2 DIFERENCIALES, 2P | D36: 25 | E36: 2 | F36: 2 | G36: 23.31
B37: 3 | C37: CABLEADO 3 DIFERENCIALES, 2P | D37: 25 | E37: 2 | F37: 3 | G37: 27.46
B38: 4 | C38: CABLEADO 4 DIFERENCIALES, 2P | D38: 25 | E38: 2 | F38: 4 | G38: 31.61
B39: 5 | C39: CABLEADO 5 DIFERENCIALES, 2P | D39: 25 | E39: 2 | F39: 5 | G39: 35.76
B40: 6 | C40: CABLEADO 6 DIFERENCIALES, 2P | D40: 25 | E40: 2 | F40: 6 | G40: 39.92
B41: 7 | C41: CABLEADO 7 DIFERENCIALES, 2P | D41: 25 | E41: 2 | F41: 7 | G41: 44.07
B42: 8 | C42: CABLEADO 8 DIFERENCIALES, 2P | D42: 25 | E42: 2 | F42: 8 | G42: 48.22
B43: 9 | C43: CABLEADO 9 DIFERENCIALES, 2P | D43: 25 | E43: 2 | F43: 9 | G43: 52.37
B44: 10 | C44: CABLEADO 10 DIFERENCIALES, 2P | D44: 25 | E44: 2 | F44: 10 | G44: 56.53
B45: 11 | C45: CABLEADO 11 DIFERENCIALES, 2P | D45: 25 | E45: 2 | F45: 11 | G45: 60.68
... B54: 20 | C54: CABLEADO 20 DIFERENCIALES, 2P | D54: 25 | E54: 2 | F54: 20 | G54: 98.05
...

Sheet Borneras
C2: COSTO CABLEADO A BORNERAS
C4: INGRESAR CANTIDADES DE BORNERAS
C5: =Materiales!D117 -> Bornera de 4mm2/10AWG, 32A, Riel Din, Tipo Tornillo, MRK-4, ONKA | D5: cant. | E5: 10
C6: =Materiales!D118 -> Bornera de 6mm2/8AWG, 41A, Riel Din, tipo Tornillo, MRK-6, ONKA | D6: cant. | E6: 5
C7: =Materiales!D119 -> Bornera de 10mm2/8AWG, 57A, Riel Din, tipo tornillo, MRK-10, ONKA | D7: cant. | E7: 0
C8: =Materiales!D120 -> Bornera de 16mm2/6AWG, 76A, Riel Din, tipo tornillo, MRK-16, ONKA | D8: cant. | E8: 0
C10: CABLEADO DE BORNERAS | D10: UNIDAD | E10: CANTIDAD | F10: PRECIO S/ | G10: SUB TOTAL S/
C11: =Materiales!D111 -> Cable NH-80, 4mm2, 32A, INDECO | D11: m | E11: =E5 -> 10 | F11: =Materiales!G111 -> 2.0762712 | G11: =E11*F11 -> 20.762712
C12: =Materiales!D112 -> Cable NH-80, 6mm2, 41A, INDECO | D12: m | E12: =E6 -> 5 | F12: =Materiales!G112 -> 3.21 | G12: =E12*F12 -> 16.05
C13: =Materiales!D113 -> Cable NH-80, 10mm2, 57A, INDECO | D13: m | E13: =E7 -> 0 | F13: =Materiales!G113 -> 5.1 | G13: =E13*F13 -> 0
C14: =Materiales!D114 -> Cable NH-80, 16mm2, 76A, INDECO | D14: m | E14: =E8 -> 0 | F14: =Materiales!G114 -> 8.5 | G14: =E14*F14 -> 0
C15: =C10 -> CABLEADO DE BORNERAS | G15: =SUM(G11:G14) -> 36.812712
C18: RESUMEN CABLEADO BORNERAS 4MM2
C19: DESCRIPCION | D19: CALIBRE | E19: AMPERAJE | F19: CANT. | G19: PRECIO (S/)
C20: CABLEADO 2 BORNERAS | D20: 4mm2 | E20: 32 | F20: 2 | G20: 4.15
C21: CABLEADO 3 BORNERAS | D21: 4mm2 | E21: 32 | F21: 3 | G21: 6.23
C22: CABLEADO 4 BORNERAS | D22: 4mm2 | E22: 32 | F22: 4 | G22: 8.31
C23: CABLEADO 5 BORNERAS | D23: 4mm2 | E23: 32 | F23: 5 | G23: 10.38
C24: CABLEADO 6 BORNERAS | D24: 4mm2 | E24: 32 | F24: 6 | G24: 12.46
C25: CABLEADO 7 BORNERAS | D25: 4mm2 | E25: 32 | F25: 7 | G25: 14.53
C26: CABLEADO 8 BORNERAS | D26: 4mm2 | E26: 32 | F26: 8 | G26: 16.61
C27: CABLEADO 9 BORNERAS | D27: 4mm2 | E27: 32 | F27: 9 | G27: 18.69
C28: CABLEADO 10 BORNERAS | D28: 4mm2 | E28: 32 | F28: 10 | G28: 20.76
C29: CABLEADO 11 BORNERAS | D29: 4mm2 | E29: 32 | F29: 11 | G29: 22.84
C30: CABLEADO 12 BORNERAS | D30: 4mm2 | E30: 32 | F30: 12 | G30: 24.92
C31: CABLEADO 13 BORNERAS | D31: 4mm2 | E31: 32 | F31: 13 | G31: 26.99
... C38: CABLEADO 20 BORNERAS | D38: 4mm2 | E38: 32 | F38: 20 | G38: 41.53

Sheet Empotrado 
B2: COSTO GABINETE EMPOTRADO
C4: Descripcion | E4: Precio (S/) | G4: Tipo de Cambio | H4: =Materiales!G73 -> 3.8
C5: =Materiales!D82 -> Plancha Galvanizada 1.5mm 1200x2400mm. | E5: =Materiales!G82 -> 130.378
C6: =Materiales!D78 -> Plancha LAF 1.5mm 1200x2400mm. | E6: =Materiales!G78 -> 114.76
C8: Dimensiones plancha | E8: 1200x2400mm.
C9: Area de plancha Plancha | E9: =1.2*2.4 -> 2.88
C11: Dimensiones del Gabinete (mm.)
C12: Alto | D12: 1400
C13: Ancho | D13: 600
C14: Profundidad | D14: 150
C16: Costo Material para Gabinete Empotrado | E16: =C5 -> Plancha Galvanizada 1.5mm 1200x2400mm. | T16: 30 dias
C17: Descripcion | E17: Unidad | F17: Cantidad
C18: Caja (laterales) | E18: m2 | F18: =+(D12)/1000*(D13-3+(D14-3)*2+10+10)/1000 -> 1.2754 | T18: 8 horas diarias
C19: Base y Techo | E19: m2 | F19: =+((D13-3-3+15+15)/1000*(D14-5+12+15)/1000)*2 -> 0.214656 | S19: H-H(Operario) | T19: =+W19/30/7 -> 9.5238095 | V19: Sueldo Operario | W19: 2000
E20: Total (m2) | F20: =SUM(F18:F19) -> 1.490056 | S20: H-H(Ayudante) | T20: =+W20/30/7 -> 7.6190476 | V20: Sueldo Ayudante | W20: 1600
E21: Cantidad Plancha | F21: =+F20/E9 -> 0.51738056
E22: Costo | F22: =+F21*E5 -> 67.455042
E23: Merma 30% | F23: =F22*0.3 -> 20.236513
E24: Costo + merma | F24: =F22+F23 -> 87.691555
C26: Costo Material para Gabinete Empotrado | E26: =C6 -> Plancha LAF 1.5mm 1200x2400mm.
C27: Descripcion | E27: Unidad | F27: Cantidad
C28: Tapapuerta | E28: m2 | F28: =+(D12+60)/1000*(D13+60)/1000 -> 0.9636
C29: Mandil | E29: m2 | F29: =+(D12-70+15+15)/1000*(D13-70+15+15)/1000 -> 0.7616
C30: Placa Base | E30: m2 | F30: =+(D12-70+15+15)/1000*(D13-70+15+15)/1000 -> 0.7616
C31: Borde superior e inferior | E31: m2 | F31: =+(D13-82)/1000*(151)/1000*2 -> 0.156436
C32: Borde Lateral | E32: m2 | F32: =+(D12+24)/1000*(132)/1000*2 -> 0.375936
E33: Total (m2) | F33: =SUM(F28:F32) -> 3.019172
E34: Cantidad Plancha | F34: =+F33/E9 -> 1.0483236
E35: Costo | F35: =+F34*E6 -> 120.30562
E36: Merma 30% | F36: =F35*0.3 -> 36.091685
E37: Costo + merma | F37: =F35+F36 -> 156.3973
C39: PINTADO, INSUMOS Y ACCESORIOS - GABINETE EMPOTRADO
C40: Descripción | D40: Cant. | E40: Und. | F40: P.U (S/) | G40: P.T (S/)
C41: =Materiales!D83 -> Pintura polvo m2 | D41: =(+F33)*2/5 -> 1.2076688 | E41: Kg | F41: =Materiales!G83 -> 19 | G41: =+F41*D41 -> 22.945707
C42: =Materiales!D142 -> Bisagra Piano para empotrado | D42: =D12/1000 -> 1.4 | E42: m | F42: =Materiales!G142 -> 20 | G42: =+F42*D42 -> 28
C43: =Materiales!D84 -> Chapa Push boton | D43: 4 | E43: Und | F43: =Materiales!G84 -> 6 | G43: =+F43*D43 -> 24
C44: =Materiales!D139 -> Pernos Gabinete empotrado | D44: 1 | E44: Glb. | F44: =Materiales!G139 -> 20 | G44: =+F44*D44 -> 20
C45: =Materiales!D138 -> Lijas y trapo industrial | D45: 1 | E45: Und | F45: =Materiales!G138 -> 2.5 | G45: =+F45*D45 -> 2.5
C46: =Materiales!D145 -> Portaplanos empotrado | D46: 1 | E46: Und | F46: =Materiales!G145 -> 10 | G46: =F46*D46 -> 10
C47: =Materiales!D149 -> Rotulo Logo peligro pintado | D47: 1 | E47: Glb. | F47: =Materiales!G149 -> 10 | G47: =+F47*D47 -> 10
...

Sheet Adosado
B2: COSTO GABINETE ADOSADO
C4: Descripcion | E4: Precio (S/) | G4: Tipo de cambio | H4: =Materiales!G73 -> 3.8
C5: =+Materiales!D79 -> Plancha LAF 2.0mm 1200x2400mm. | E5: =+Materiales!G79 -> 152.912
C7: Dimensiones plancha | E7: 1200x2400mm.
C8: Area de plancha Plancha | E8: =1.2*2.4 -> 2.88
C10: Dimensiones del Gabinete (mm.)
C11: Alto | D11: 550
C12: Ancho | D12: 450
C13: Profundidad | D13: 150
C15: Costo Material para gabinete Adosado | E15: =C5 -> Plancha LAF 2.0mm 1200x2400mm.
C16: Descripcion | E16: Unidad | F16: Cantidad
C17: Caja | E17: m2 | F17: =+D11/1000*((D12-3)/1000+(D13-3)/1000*2+(30+12+8)/1000*2) -> 0.46255 | J17: MANO DE OBRA E INSUMOS - GABINETE ADOSADO
C18: Base | E18: m2 | F18: =+((D12-6+15+15)/1000*(D13-5+30+12+8+15)/1000) -> 0.09954 | J18: Descripción | K18: Cant. | L18: Unid. | M18: P.U (S/) | N18: P.T (S/)
C19: Techo | E19: m2 | F19: =+F18 -> 0.09954 | J19: Lijas | K19: 1 | L19: Unid. | M19: 1.2 | N19: =+M19*K19 -> 1.2
C20: Puerta | E20: m2 | F20: =+(D12-8+12+12)/1000*(D11-8+12+12)/1000 -> 0.263756 | J20: Trapos | K20: 2 | L20: Unid. | M20: 0.25 | N20: =+M20*K20 -> 0.5
C21: Placa Base | E21: m2 | F21: =+(D11-75+15+15)/1000*(D12-75+15+15)/1000 -> 0.204525 | J21: Pernos | K21: 1 | L21: Glb. | M21: 10 | N21: =+M21*K21 -> 10
C22: Mandil | E22: m2 | F22: =+F21 -> 0.204525 | J22: Logo Peligro | K22: 1 | L22: Glb. | M22: 10 | N22: =+M22*K22 -> 10
E23: Total (m2) | F23: =SUM(F17:F22) -> 1.334436 | J23: M.O. Mecanica | K23: 1 | L23: Glb. | M23: =(S12+S13)*2 -> 0 | N23: =+M23*K23 -> 0 | O23: =SUM(N23:N26) -> 0
E24: Cantidad Plancha | F24: =+(F23/E8) -> 0.46334583 | J24: M.O. Soldadura | K24: 1 | L24: Glb. | M24: =(S12+S13)*2.5 -> 0 | N24: =+M24*K24 -> 0
E25: Costo | F25: =+F24*E5 -> 70.851138 | J25: M.O. Pintura | K25: 1 | L25: Glb. | M25: =(S12+S13)*2.5 -> 0 | N25: =+M25*K25 -> 0
E26: Merma 30% | F26: =F25*0.3 -> 21.255341 | J26: M.O. Armado | K26: 1 | L26: Glb. | M26: =(S12+S13)*3 -> 0 | N26: =+M26*K26 -> 0
E27: Costo + merma | F27: =F25+F26 -> 92.106479 | J27: Bisagra | K27: 4 | L27: Unid. | M27: 5 | N27: =+M27*K27 -> 20
J28: Frisa | L28: m | M28: 3 | N28: =+M28*D37 -> 6
J29: Chapa | K29: 4 | L29: Unid. | M29: 8 | N29: =+M29*K29 -> 32
J30: Pintura | K30: =+F23/5*2 -> 0.5337744 | L30: Kg | M30: 18.5 | N30: =+M30*K30 -> 9.8748264
C31: PINTADO, INSUMOS Y ACCESORIOS - GABINETE EMPOTRADO | J31: Portaplanos | K31: 1 | L31: Glb. | M31: 10 | N31: =M31*K31 -> 10
C32: Descripción | D32: Cant. | E32: Und. | F32: P.U (S/) | G32: P.T (S/) | J32: Embalado | K32: 1 | L32: Glb. | M32: 10 | N32: =M32*K32 -> 10
C33: =Materiales!D83 -> Pintura polvo m2 | D33: =(+F23)*2/5 -> 0.5337744 | E33: Kg | F33: =Materiales!G83 -> 19 | G33: =+F33*D33 -> 10.141714 | M33: Sub-Total | N33: =SUM(N19:N32) -> 109.57483
C34: =Materiales!D143 -> Bisagra de 3 puntos HL011-1, Adosados | D34: 2 | E34: Und. | F34: =Materiales!G143 -> 5 | G34: =+F34*D34 -> 10
C35: =Materiales!D85 -> Chapa Circular con llave metal MS705-1-1 TKL, ACSA | D35: 1 | E35: Und | F35: =Materiales!G85 -> 6.5 | G35: =+F35*D35 -> 6.5 | J35: Costo Total | K35: =+N33+F25+P17 -> 180.42596 | L35: Margen | M35: 0.3
C36: =Materiales!D140 -> Pernos Gabinete adosado | D36: 1 | E36: Glb. | F36: =Materiales!G140*0.4 -> 8 | G36: =+F36*D36 -> 8 | J36: Margen | K36: =+M35*K35 -> 54.127789
C37: =Materiales!D136 -> Frisa plana Adhesiva 1" X 5 MM | D37: =+D11/1000*2+D12/1000*2 -> 2 | E37: m | F37: =Materiales!G136 -> 2.12 | G37: =F37*D37 -> 4.24
C38: =Materiales!D138 -> Lijas y trapo industrial | D38: 1 | E38: Und | F38: =Materiales!G138 -> 2.5 | G38: =+F38*D38 -> 2.5 | J38: P.Venta | K38: =+K36+K35 -> 234.55375
C39: =Materiales!D146 -> Portaplanos adosado | D39: 1 | E39: Glb. | F39: =Materiales!G146*0.5 -> 5 | G39: =+F39*D39 -> 5
C40: =Materiales!D149 -> Rotulo Logo peligro pintado | D40: 1 | E40: Und | F40: =Materiales!G149*0.8 -> 8 | G40: =F40*D40 -> 8
C41: =Materiales!D150 -> Rotulo placa Nombre de tablero | D41: 1 | E41: Glb. | F41: =Materiales!G150 -> 5.5 | G41: =F41*D41 -> 5.5 | J41: 24
C42: =Materiales!D151 -> Rotulo placa circuitos derivados | D42: 12 | E42: Und | F42: =Materiales!G151 -> 1.5 | G42: =F42*D42 -> 18 | J42: 12
C43: =Materiales!D153 -> Embalaje Adosado | D43: 1 | E43: Und | F43: =Materiales!G153 -> 10 | G43: =F43*D43 -> 10
C44: =Materiales!D155 -> Dossier, hojas, micas impresiones (Adosado-Empotrado) | D44: 1 | E44: Glb. | F44: =Materiales!G155 -> 10 | G44: =F44*D44 -> 10
C45: =Materiales!D157 -> Desgaste de Maquinarias Adosado y empotrado | D45: 1 | E45: Glb. | F45: =Materiales!G157*0.3 -> 15 | G45: =+F45*D45 -> 15
...

Sheet Autosoportado
B2: COSTO GABINETE AUTOSOPORTADO
C4: Descripcion | E4: Precio (S/) | G4: Tipo de Cambio | H4: 3.8 | M4: dimensiones plancha | O4: area plancha
C5: =+Materiales!$D$81 -> Plancha LAF 3mm 1200x2400mm. | E5: =+Materiales!$G$81 -> 207.62712
C6: =+Materiales!$D$81 -> Plancha LAF 3mm 1200x2400mm. | E6: =+Materiales!$G$81 -> 207.62712
C7: =+Materiales!$D$81 -> Plancha LAF 3mm 1200x2400mm. | E7: =+Materiales!$G$81 -> 207.62712
C9: Dimensiones plancha | E9: 1200x2400mm.
C10: Area de plancha Plancha | E10: =1.2*2.4 -> 2.88
C12: Dimensiones del Gabinete (mm.) | M12: 1200x2400x1450mm. | P12: mm.
C13: Alto | D13: 2000
C14: Ancho | D14: 800
C15: Profundidad | D15: 450
C17: Costo Material: Cuerpo, Techo y puerta | F17: =C6 -> Plancha LAF 3mm 1200x2400mm. | S17: 8 horas diarias
C18: Descripcion | E18: A1 | F18: A2 | G18: AT
C19: Techo | E19: =+(D14-4+(46+25+18)*2)/1000 -> 0.974 | F19: =+(D15-4+25+18+46+46+15+10)/1000 -> 0.606 | G19: =+F19*E19 -> 0.590244 | R19: Hora-Hombre(Operario) | S19: =+V19/30/8 -> 8.3333333 | U19: Sueldo | V19: 2000
C20: Puerta | E20: =+(D14-5-4+20+10+18)/1000*2 -> 1.678 | F20: =+(D13-100-5-4+20+20)/1000 -> 1.931 | G20: =+F20*E20 -> 3.240218 | R20: Hora-Hombre(Ayudante) | S20: =+V20/30/8 -> 6.6666667 | U20: Sueldo | V20: 1600
C21: Parante Posterior | E21: =+(D13-100+4)/1000 -> 1.904 | F21: =+(180)/1000 -> 0.18 | G21: =+F21*E21*2 -> 0.68544
C22: Parante Frontal | E22: =+(D13-100+4)/1000 -> 1.904 | F22: =+(162)/1000 -> 0.162 | G22: =+F22*E22*2 -> 0.616896
C23: Base Posterior | E23: =+(D14-4)/1000 -> 0.796 | F23: =+(119)/1000 -> 0.119 | G23: =+F23*E23 -> 0.094724
C24: Base Frontal | E24: =+(D14-4)/1000 -> 0.796 | F24: =+(137)/1000 -> 0.137 | G24: =+F24*E24 -> 0.109052
C25: Base Lateral | E25: =+(D15-4)/1000 -> 0.446 | F25: =+(137)/1000 -> 0.137 | G25: =+F25*E25*2 -> 0.122204
F26: Total (m2) | G26: =SUM(G19:G25) -> 5.458778
F27: Cantidad Plancha | G27: =G26/E10 -> 1.895409
F28: Costo | G28: =+G27*E6 -> 393.53832
F29: Merma 30% | G29: =G28*0.3 -> 118.06149
F30: Costo + merma | G30: =G28+G29 -> 511.59981
C32: Costo Material: Paneles posteriores y laterales | F32: =C5 -> Plancha LAF 3mm 1200x2400mm.
C33: Panel Posterior | E33: =+(D14-50-50-3-4+18+18)/1000 -> 0.729 | F33: =+(D13-100-50-50-3-4+18+18)/1000 -> 1.829 | G33: =+(D14-50-50-3-4+18+18)/1000*(D13-100-50-50-3-4+18+18)/1000 -> 1.333341
C34: Panel Lateral | E34: =+(D15-50-50-3-4+18+18)/1000 -> 0.379 | F34: =+(D13-100-50-50-3-4+18+18)/1000 -> 1.829 | G34: =+((D15-50-50-3-4+18+18)/1000*(D13-100-50-50-3-4+18+18)/1000)*2 -> 1.386382
F35: Total (m2) | G35: =SUM(G33:G34) -> 2.719723
F36: Cantidad Plancha | G36: =G35/E10 -> 0.94434826
F37: Costo | G37: =+G36*E6 -> 196.07231
F38: Merma 30% | G38: =G37*0.3 -> 58.821693
F39: Costo + merma | G39: =G37+G38 -> 254.894
C41: Costo Material: Zocalo | F41: =C7 -> Plancha LAF 3mm 1200x2400mm.
C42: Zócalo Frontal | G42: =+(D14-5)/1000*(212)/1000 -> 0.16854
C43: Zócalo posterior | G43: =+(D14-5)/1000*(212)/1000 -> 0.16854
C44: Zócalo lateral | G44: =+(D15-5)/1000*(212)/1000 -> 0.09434
F45: Total (m2) | G45: =SUM(G42:G44) -> 0.43142
F46: Cantidad Plancha | G46: =+G45/E10 -> 0.14979861
F47: Costo | G47: =+G46*E7 -> 31.102254
...

Sheet M. Obra Autosoportado
B2: COSTO DE MANO DE OBRA PLANTA, ADMINISTRATIVOS Y SERVICIOS
I4: Dias de trabajo | J4: 30
I5: Horas de trabajo | J5: 8
B7: MANO DE OBRA GABINETE AUTOSOPORTADO
E9: Con beneficios | H9: POR 1 TABLERO AUTOSOPORTADO | P9: POR 10 TABLEROS | S9: POR 50 TABLEROS | V9: POR 100 TABLEROS
B10: MANO DE OBRA PLANTA | D10: Sueldos (S/) | E10: 1.35 | F10: COSTO POR DIA | G10: COSTO POR HORA | H10: Tiempo trabajo (Hora) | I10: Dias de trabajo | J10: Costo trabajo (S/) | P10: Dias de trabajo | Q10: Tiempo trabajo (Hora) | R10: Costo trabajo (S/) | S10: Dias de trabajo | T10: Tiempo trabajo (Hora) | U10: Costo trabajo (S/) | V10: Dias de trabajo | W10: Tiempo trabajo (Hora) | X10: Costo trabajo (S/)
B11: Mecanica | C11: Operario | D11: 2400 | E11: =+D11*E10 -> 3240 | F11: =+E11/J4 -> 108 | G11: =+F11/J5 -> 13.5 | I11: 1 | J11: =+I11*F11 -> 108 | P11: - | Q11: 3 | R11: =+Q11*G11 -> 40.5 | S11: 1.5 | T11: - | U11: =+S11*F11 -> 162 | V11: 2.5 | W11: - | X11: =+V11*F11 -> 270
C12: Ayudante | D12: 2000 | E12: =+D12*E10 -> 2700 | F12: =+E12/J4 -> 90 | G12: =+F12/J5 -> 11.25 | I12: 1 | J12: =+I12*F12 -> 90 | P12: - | Q12: 3 | R12: =+Q12*G12 -> 33.75 | S12: 1.5 | T12: - | U12: =+S12*F12 -> 135 | V12: 2.5 | W12: - | X12: =+V12*F12 -> 225
B13: Soldadura | C13: Operario | D13: 2400 | E13: =+D13*E10 -> 3240 | F13: =+E13/J4 -> 108 | G13: =+F13/J5 -> 13.5 | I13: 1 | J13: =+I13*F13 -> 108 | P13: - | Q13: 5 | R13: =+Q13*G13 -> 67.5 | S13: 1 | T13: - | U13: =+S13*F13 -> 108 | V13: 2.5 | W13: - | X13: =+V13*F13 -> 270
C14: Ayudante | D14: 2000 | E14: =+D14*E10 -> 2700 | F14: =+E14/J4 -> 90 | G14: =+F14/J5 -> 11.25 | I14: 1 | J14: =+I14*F14 -> 90 | P14: - | Q14: 5 | R14: =+Q14*G14 -> 56.25 | S14: 1 | T14: - | U14: =+S14*F14 -> 90 | V14: 2.5 | W14: - | X14: =+V14*F14 -> 225
B15: Pintura | C15: operario | D15: 2400 | E15: =+D15*E10 -> 3240 | F15: =+E15/J4 -> 108 | G15: =+F15/J5 -> 13.5 | I15: 1 | J15: =+I15*F15 -> 108 | P15: 0.5 | Q15: - | R15: =+P15*F15 -> 54 | S15: 1.5 | T15: - | U15: =+S15*F15 -> 162 | V15: 3 | W15: - | X15: =+V15*F15 -> 324
C16: Ayudante | D16: 2000 | E16: =+D16*E10 -> 2700 | F16: =+E16/J4 -> 90 | G16: =+F16/J5 -> 11.25 | I16: 1 | J16: =+I16*F16 -> 90 | P16: 0.5 | Q16: - | R16: =+P16*F16 -> 45 | S16: 1.5 | T16: - | U16: =+S16*F16 -> 135 | V16: 3 | W16: - | X16: =+V16*F16 -> 270
B17: Barras | C17: operario | D17: 2400 | E17: =+D17*E10 -> 3240 | F17: =+E17/J4 -> 108 | G17: =+F17/J5 -> 13.5 | H17: - | J17: =+I17*F17 -> 0 | P17: - | Q17: 6 | R17: =+Q17*G17 -> 81 | S17: 1.5 | T17: - | U17: =+S17*F17 -> 162 | V17: 3 | W17: - | X17: =+V17*F17 -> 324
C18: Ayudante | D18: 2000 | E18: =+D18*E10 -> 2700 | F18: =+E18/J4 -> 90 | G18: =+F18/J5 -> 11.25 | H18: - | J18: =+I18*F18 -> 0 | P18: - | Q18: 6 | R18: =+Q18*G18 -> 67.5 | S18: 1.5 | T18: - | U18: =+S18*F18 -> 135 | V18: 3 | W18: - | X18: =+V18*F18 -> 270
B19: Ensamble | C19: Operario | D19: 2400 | E19: =+D19*E10 -> 3240 | F19: =+E19/J4 -> 108 | G19: =+F19/J5 -> 13.5 | H19: - | I19: 1 | J19: =+I19*F19 -> 108 | P19: 1 | Q19: - | R19: =+P19*F19 -> 108 | S19: 2.5 | T19: - | U19: =+S19*F19 -> 270 | V19: 4 | W19: - | X19: =+V19*F19 -> 432
C20: Ayudante | D20: 2000 | E20: =+D20*E10 -> 2700 | F20: =+E20/J4 -> 90 | G20: =+F20/J5 -> 11.25 | H20: - | I20: 1 | J20: =+I20*F20 -> 90 | P20: 1 | Q20: - | R20: =+P20*F20 -> 90 | S20: 2.5 | T20: - | U20: =+S20*F20 -> 225 | V20: 4 | W20: - | X20: =+V20*F20 -> 360
B21: Embalaje | C21: Operario | D21: 2400 | E21: =+D21*E10 -> 3240 | F21: =+E21/J4 -> 108 | G21: =+F21/J5 -> 13.5 | H21: 1 | J21: =+H21*G21 -> 13.5 | P21: - | Q21: 2 | R21: =+Q21*G21 -> 27 | S21: - | T21: 5 | U21: =+T21*G21 -> 67.5 | V21: 1.5 | W21: - | X21: =+V21*F21 -> 162
C22: Ayudante | D22: 2000 | E22: =+D22*E10 -> 2700 | F22: =+E22/J4 -> 90 | G22: =+F22/J5 -> 11.25 | H22: 1 | J22: =+H22*G22 -> 11.25 | P22: - | Q22: 2 | R22: =+Q22*G22 -> 22.5 | S22: - | T22: 5 | U22: =+T22*G22 -> 56.25 | V22: 1.5 | W22: - | X22: =+V22*F22 -> 135
B23: Almacen | C23: Operario | D23: 2400 | E23: =+D23*E10 -> 3240 | F23: =+E23/J4 -> 108 | G23: =+F23/J5 -> 13.5 | H23: 1 | J23: =+H23*G23 -> 13.5 | P23: 1 | Q23: - | R23: =+P23*F23 -> 108 | S23: 1 | T23: - | U23: =+S23*F23 -> 108 | V23: 1 | W23: - | X23: =+V23*F23 -> 108
C24: Ayudante | D24: 2000 | E24: =+D24*E10 -> 2700 | F24: =+E24/J4 -> 90 | G24: =+F24/J5 -> 11.25 | H24: 1 | J24: =+H24*G24 -> 11.25 | P24: 1 | Q24: - | R24: =+P24*F24 -> 90 | S24: 1 | T24: - | U24: =+S24*F24 -> 90 | V24: 1 | W24: - | X24: =+V24*F24 -> 90
J25: =SUM(J11:J24) -> 841.5
E28: Con beneficios | H28: POR 1 TABLERO AUTOSOPORTADO
B29: MANO DE OBRA PLANTA | D29: Sueldos (S/) | E29: 1.35 | F29: COSTO POR DIA | G29: COSTO POR HORA | H29: Tiempo trabajo (Hora) | I29: Dias de trabajo | J29: Costo trabajo (S/)
B30: Electricidad | C30: Operario | D30: 2400 | E30: =+D30*E10 -> 3240 | F30: =+E30/J4 -> 108 | G30: =+F30/J5 -> 13.5 | H30: - | I30: 3 | J30: =+I30*F30 -> 324
C31: Ayudante 1 | D31: 2000 | E31: =+D31*E10 -> 2700 | F31: =+E31/J4 -> 90 | G31: =+F31/J5 -> 11.25 | H31: - | I31: 3 | J31: =+I31*F31 -> 270
C32: Ayudante 2 | D32: 1600 | E32: =+D32*E10 -> 2160 | F32: =+E32/J4 -> 72 | G32: =+F32/J5 -> 9 | H32: - | I32: 3 | J32: =+I32*F32 -> 216
J33: =+SUM(J30:J32) -> 810
E36: Con beneficios | H36: POR 1 TABLERO AUTOSOPORTADO
B37: M. DE OBRA (TIPO 1 AL 6) MONTAJE AIRE ACONDICIONADO Y ACCESORIOS | D37: Sueldos (S/) | E37: 1.35 | F37: COSTO POR DIA | G37: COSTO POR HORA | H37: Tiempo trabajo (Hora) | I37: Dias de trabajo | J37: Costo trabajo (S/)
B38: Electricidad | C38: Operario | D38: 2400 | E38: =+D38*E37 -> 3240 | F38: =+E38/J4 -> 108 | G38: =+F38/J5 -> 13.5 | H38: - | I38: 3.5 | J38: =+I38*F38 -> 378
C39: Ayudante 1 | D39: 2000 | E39: =+D39*E37 -> 2700 | F39: =+E39/J4 -> 90 | G39: =+F39/J5 -> 11.25 | H39: - | I39: 3.5 | J39: =+I39*F39 -> 315
C40: Ayudante 2 | D40: 1600 | E40: =+D40*E37 -> 2160 | F40: =+E40/J4 -> 72 | G40: =+F40/J5 -> 9 | H40: - | I40: 3.5 | J40: =+I40*F40 -> 252
J41: =+SUM(J38:J40) -> 945
E43: Con beneficios | H43: POR 1 TABLERO AUTOSOPORTADO
B44: M. DE OBRA (TIPO 7 y 8) MONTAJE AIRE ACONDICIONADO Y ACCESORIOS | D44: Sueldos (S/) | E44: 1.35 | F44: COSTO POR DIA | G44: COSTO POR HORA | H44: Tiempo trabajo (Hora) | I44: Dias de trabajo | J44: Costo trabajo (S/)
B45: Electricidad | C45: Operario | D45: 2400 | E45: =+D45*E44 -> 3240 | F45: =+E45/J4 -> 108 | G45: =+F45/J5 -> 13.5 | H45: - | I45: 4.5 | J45: =+I45*F45 -> 486
C46: Ayudante 1 | D46: 2000 | E46: =+D46*E44 -> 2700 | F46: =+E46/J4 -> 90 | G46: =+F46/J5 -> 11.25 | H46: - | I46: 4.5 | J46: =+I46*F46 -> 405
C47: Ayudante 2 | D47: 1600 | E47: =+D47*E44 -> 2160 | F47: =+E47/J4 -> 72 | G47: =+F47/J5 -> 9 | H47: - | I47: 4.5 | J47: =+I47*F47 -> 324
J48: =+SUM(J45:J47) -> 1215
E50: Con beneficios | H50: POR 1 TABLERO AUTOSOPORTADO
...

Sheet Cobre Autosoportado
B2: CALCULO DE COSTO BARRAS DE COBRE Y ACCESORIOS EN AUTOSOPORTADOS | I2: Tipo 1 | J2: Tipo 2 al 6 y 8 | K2: 7 | L2: 9, 9.1 y 10.1 | M2: 10 | N2: 11, 12, 12.1 y 13 | O2: 14 y 14.1 | P2: 15
I3: 250 | J3: 250 | K3: 500 | L3: 500 | M3: 750 | N3: 750 | O3: 1000 | P3: 1250
G4: T. Cambio | H4: 3.8 | I4: 160 | J4: 160 | K4: 80 | L4: 160 | M4: 160 | N4: 160 | O4: 160 | P4: 160
K5: 80 | L5: 160 | M5: 160 | N5: 160 | O5: 160 | P5: 160
N6: 160 | O6: 160
O7: 160
I8: =SUM(I3:I7) -> 410 | J8: =SUM(J3:J7) -> 410 | K8: =SUM(K3:K7) -> 660 | L8: =SUM(L3:L7) -> 820 | M8: =SUM(M3:M7) -> 1070 | N8: =SUM(N3:N7) -> 1230 | O8: =SUM(O3:O7) -> 1640 | P8: =SUM(P3:P7) -> 1570
B9: =+Hoja4!C7 -> COBRE BUS BAR TIPO 1; 2; 3; 4; 4.1; 5; 7
B10: ITEM | C10: DESCRIPCION | D10: BARRA DE CU | E10: CANTIDAD | F10: UNIDAD | G10: PRECIO (S/) | H10: SUB TOTAL (S/) | I10: A | J10: Largo | K10: Suples 1 | L10: Suples 2 | M10: Fases | N10: N° Barras | O10: Cant Interruptores
B11: 1 | C11: Cu Barras Colectoras 2P | D11: =+Barras!A17 -> 30 x 10 | E11: =SUM(J11:L11)*M11*N11*O11 -> 2 | F11: m | G11: =VLOOKUP(D11,Barras!$A$6:$T$31,20,0) -> 123.95 | H11: =+E11*G11 -> 247.9 | I11: =+Hoja4!L7 -> 497 | J11: 1 | K11: 0 | L11: 0 | M11: 2 | N11: 1 | O11: 1
B12: 2 | C12: Cu Derivaciones 2P (250A) Bateria | D12: =+Barras!A13 -> 25 x 3 | E12: =SUM(J12:L12)*M12*N12*O12 -> 0.7 | F12: m | G12: =VLOOKUP(D12,Barras!$A$6:$T$31,20,0) -> 31.45 | H12: =G12*E12 -> 22.015 | I12: 250 | J12: 0 | K12: 0.35 | L12: 0 | M12: 2 | N12: 1 | O12: 1
B13: 3 | C13: Cu Derivaciones 2P (160A) Controlador | D13: =+Barras!A8 -> 15 x 3 | E13: =SUM(J13:L13)*M13*N13*O13 -> 0.7 | F13: m | G13: =VLOOKUP(D13,Barras!$A$6:$T$31,20,0) -> 18.5 | H13: =+E13*G13 -> 12.95 | I13: 160 | J13: 0 | K13: 0.35 | L13: 0 | M13: 2 | N13: 1 | O13: 1
B14: 3 | C14: Cu Derivaciones 2P (63A) Inversor | D14: =+Barras!A8 -> 15 x 3 | E14: =SUM(J14:L14)*M14*N14*O14 -> 1.4 | F14: m | G14: =VLOOKUP(D14,Barras!$A$6:$T$31,20,0) -> 18.5 | H14: =+E14*G14 -> 25.9 | I14: 160 | J14: 0 | K14: 0.35 | L14: 0 | M14: 2 | N14: 1 | O14: 2
B15: 4 | C15: Cu Barra a tierra | D15: =+Barras!A16 -> 30 x 5 | E15: =SUM(J15:L15)*M15*N15*O15 -> 0.7 | F15: m | G15: =VLOOKUP(D15,Barras!$A$6:$T$31,20,0) -> 62.21 | H15: =+E15*G15 -> 43.547 | J15: 0.7 | K15: 0 | L15: 0 | M15: 1 | N15: 1 | O15: 1
B16: 5 | C16: Aisladores | D16: Cl 1/1000 | E16: 6 | F16: Pza | G16: =+Materiales!G88 -> 3.81 | H16: =+E16*G16 -> 22.86
B17: 6 | C17: Perneria | D17: Otros | E17: 1 | F17: Glb. | G17: 25 | H17: =G17*E17 -> 25
B18: 7 | C18: Placa de Fabricante | D18: 250x100mm | E18: 1 | F18: Pza | G18: 5.5 | H18: =+E18*G18 -> 5.5
B19: 8 | C19: Placa de Identificación Tablero | D19: 140x40mm | E19: 1 | F19: Pza | G19: 6 | H19: =+E19*G19 -> 6
B20: 9 | C20: Placa de Identificación Componentes | D20: 50x20mm | E20: 13 | F20: Pza | G20: 2 | H20: =+E20*G20 -> 26
B21: =+B9 -> COBRE BUS BAR TIPO 1; 2; 3; 4; 4.1; 5; 7 | H21: =SUM(H11:H20) -> 437.672 | I21: Soles
B24: =+Hoja4!C14 -> COBRE BUS BAR TIPO 6
B25: ITEM | C25: DESCRIPCION | D25: BARRA DE CU | E25: CANTIDAD | F25: UNIDAD | G25: PRECIO (S/) | H25: SUB TOTAL (S/) | I25: A | J25: Largo | K25: Suples 1 | L25: Suples 2 | M25: Fases | N25: N° Barras | O25: Cant Interruptores
B26: 1 | C26: Cu Barras Colectoras 2P | D26: =+Barras!A17 -> 30 x 10 | E26: =SUM(J26:L26)*M26*N26*O26 -> 2 | F26: m | G26: =VLOOKUP(D26,Barras!$A$6:$T$31,20,0) -> 123.95 | H26: =+E26*G26 -> 247.9 | I26: =+Hoja4!L14 -> 676 | J26: 1 | K26: 0 | L26: 0 | M26: 2 | N26: 1 | O26: 1
B27: 2 | C27: Cu Derivaciones 2P (250A) Bateria | D27: =+Barras!A13 -> 25 x 3 | E27: =SUM(J27:L27)*M27*N27*O27 -> 1.4 | F27: m | G27: =VLOOKUP(D27,Barras!$A$6:$T$31,20,0) -> 31.45 | H27: =G27*E27 -> 44.03 | I27: 250 | J27: 0 | K27: 0.35 | L27: 0 | M27: 2 | N27: 1 | O27: 2
B28: 3 | C28: Cu Derivaciones 2P (160A) Controlador | D28: =+Barras!A8 -> 15 x 3 | E28: =SUM(J28:L28)*M28*N28*O28 -> 0.7 | F28: m | G28: =VLOOKUP(D28,Barras!$A$6:$T$31,20,0) -> 18.5 | H28: =+E28*G28 -> 12.95 | I28: 160 | J28: 0 | K28: 0.35 | L28: 0 | M28: 2 | N28: 1 | O28: 1
B29: 3 | C29: Cu Derivaciones 2P (110A) Inversor | D29: =+Barras!A8 -> 15 x 3 | E29: =SUM(J29:L29)*M29*N29*O29 -> 1.4 | F29: m | G29: =VLOOKUP(D29,Barras!$A$6:$T$31,20,0) -> 18.5 | H29: =+E29*G29 -> 25.9 | I29: 160 | J29: 0 | K29: 0.35 | L29: 0 | M29: 2 | N29: 1 | O29: 2
B30: 4 | C30: Cu Barra a tierra | D30: =+Barras!A16 -> 30 x 5 | E30: =SUM(J30:L30)*M30*N30*O30 -> 0.7 | F30: m | G30: =VLOOKUP(D30,Barras!$A$6:$T$31,20,0) -> 62.21 | H30: =+E30*G30 -> 43.547 | J30: 0.7 | K30: 0 | L30: 0 | M30: 1 | N30: 1 | O30: 1
B31: 5 | C31: Aisladores | D31: Cl 1/1000 | E31: 6 | F31: Pza | G31: =+Materiales!G88 -> 3.81 | H31: =+E31*G31 -> 22.86
B32: 6 | C32: Perneria | D32: Otros | E32: 1 | F32: Glb. | G32: 25 | H32: =G32*E32 -> 25
B33: 7 | C33: Placa de Fabricante | D33: 250x100mm | E33: 1 | F33: Pza | G33: 5.5 | H33: =+E33*G33 -> 5.5
B34: 8 | C34: Placa de Identificación Tablero | D34: 140x40mm | E34: 1 | F34: Pza | G34: 6 | H34: =+E34*G34 -> 6
B35: 9 | C35: Placa de Identificación Componentes | D35: 50x20mm | E35: 13 | F35: Pza | G35: 2 | H35: =+E35*G35 -> 26
B36: =+B24 -> COBRE BUS BAR TIPO 6 | H36: =SUM(H26:H35) -> 459.687 | I36: Soles
B39: =+Hoja4!C15 -> COBRE BUS BAR TIPO 8; 8.1 y 9.1
B40: ITEM | C40: DESCRIPCION | D40: BARRA DE CU | E40: CANTIDAD | F40: UNIDAD | G40: PRECIO (S/) | H40: SUB TOTAL (S/) | I40: A | J40: Largo | K40: Suples 1 | L40: Suples 2 | M40: Fases | N40: N° Barras | O40: Cant Interruptores
B41: 1 | C41: Cu Barras Colectoras 2P | D41: =+Barras!A20 -> 40 x 10 | E41: =SUM(J41:L41)*M41*N41*O41 -> 2.8 | F41: m | G41: =VLOOKUP(D41,Barras!$A$6:$T$31,20,0) -> 165.73 | H41: =+E41*G41 -> 464.044 | I41: =+Hoja4!L15 -> 850 | J41: 1.4 | K41: 0 | L41: 0 | M41: 2 | N41: 1 | O41: 1
B42: 2 | C42: Cu Derivaciones 2P (250A) Bateria | D42: =+Barras!A13 -> 25 x 3 | E42: =SUM(J42:L42)*M42*N42*O42 -> 1.4 | F42: m | G42: =VLOOKUP(D42,Barras!$A$6:$T$31,20,0) -> 31.45 | H42: =G42*E42 -> 44.03 | I42: 250 | J42: 0 | K42: 0.35 | L42: 0 | M42: 2 | N42: 1 | O42: 2
B43: 3 | C43: Cu Derivaciones 2P (160A) Controlador | D43: =+Barras!A8 -> 15 x 3 | E43: =SUM(J43:L43)*M43*N43*O43 -> 1.4 | F43: m | G43: =VLOOKUP(D43,Barras!$A$6:$T$31,20,0) -> 18.5 | H43: =G43*E43 -> 25.9 | I43: 160 | J43: 0 | K43: 0.35 | L43: 0 | M43: 2 | N43: 1 | O43: 2
B44: 3 | C44: Cu Derivaciones 2P (110A) Inversor | D44: =+Barras!A8 -> 15 x 3 | E44: =SUM(J44:L44)*M44*N44*O44 -> 4.2 | F44: m | G44: =VLOOKUP(D44,Barras!$A$6:$T$31,20,0) -> 18.5 | H44: =+E44*G44 -> 77.7 | I44: 160 | J44: 0 | K44: 0.35 | L44: 0 | M44: 2 | N44: 1 | O44: 6
B45: 4 | C45: Cu Barra a tierra | D45: =+Barras!A16 -> 30 x 5 | E45: =SUM(J45:L45)*M45*N45*O45 -> 0.7 | F45: m | G45: =VLOOKUP(D45,Barras!$A$6:$T$31,20,0) -> 62.21 | H45: =+E45*G45 -> 43.547 | J45: 0.7 | K45: 0 | L45: 0 | M45: 1 | N45: 1 | O45: 1
...

Sheet Hoja4
E6: BATERIA | F6: CONTROLADOR | J6: A | K6: BARRA | L6: CAPACIDAD
B7: 1 | C7: COBRE BUS BAR TIPO 1; 2; 3; 4; 4.1; 5; 7 | D7: tipo 1 | E7: 250 | F7: 160 | J7: =SUM(E7:I7) -> 410 | K7: =+Barras!A12 -> 20 x 10 | L7: =+Barras!D12 -> 497
D8: tipo 2 | E8: 250 | F8: 160
D9: tipo 3 | E9: 250 | F9: 160
D10: tipo 4 | E10: 250 | F10: 160
D11: tipo 4.1 | E11: 250 | F11: 160
D12: tipo 5 | E12: 250 | F12: 50 | G12: 50
D13: tipo 7 | E13: 250 | F13: 160
B14: 2 | C14: COBRE BUS BAR TIPO 6 | D14: tipo 6 | E14: 500 | F14: 80 | G14: 80 | J14: =SUM(E14:G14) -> 660 | K14: =+Barras!A17 -> 30 x 10 | L14: =+Barras!D17 -> 676
B15: 3 | C15: COBRE BUS BAR TIPO 8; 8.1 y 9.1 | D15: tipo 8 | E15: 500 | F15: 160 | G15: 160 | J15: =SUM(E15:G15) -> 820 | K15: =+Barras!A20 -> 40 x 10 | L15: =+Barras!D20 -> 850
D16: tipo 8.1 | E16: 500 | F16: 160 | G16: 160
D17: tipo 9.1 | E17: 500 | F17: 160 | G17: 160
B18: 4 | C18: COBRE BUS BAR TIPO 9 | D18: tipo 9 | E18: 750 | F18: 160 | G18: 160 | J18: =SUM(E18:I18) -> 1070 | K18: =+Barras!A24 -> 60 x 10 | L18: =+Barras!D24 -> 1180
B19: 5 | C19: COBRE BUS BAR TIPO 10; 10.1; 10.2; 11 | D19: tipo 10 | E19: 750 | F19: 160 | G19: 160 | H19: 160 | J19: =SUM(E19:H19) -> 1230 | K19: =+Barras!A26 -> 80 x 10 | L19: =+Barras!D26 -> 1500
D20: tipo 10.1 | E20: 750 | F20: 160 | G20: 160 | H20: 160
D21: tipo 10.2 | E21: 750 | F21: 160 | G21: 160 | H21: 160
D22: tipo 11 | E22: 750 | F22: 160 | G22: 160 | H22: 160
B23: 6 | C23: COBRE BUS BAR TIPO 12 y 12.1 | D23: tipo 12 | E23: 1000 | F23: 160 | G23: 160 | H23: 160 | I23: 160 | J23: =SUM(E23:I23) -> 1640 | K23: =+Barras!A22 -> 50 x 10 | L23: =+Barras!E22 -> 1720
D24: tipo 12.1 | E24: 1000 | F24: 160 | G24: 160 | H24: 160 | I24: 160 | K24: doble barra
B25: 7 | C25: COBRE BUS BAR TIPO 14 (C01;G01), (C02;G01), (C01;G03), (C02;G03), (C03;G01), (C03;G03) | D25: tipo 14 (C01;G01) | E25: 1000 | J25: =SUM(E30) -> 1000 | K25: =+Barras!A22 -> 50 x 10 | L25: =+Barras!D22 -> 1020
D26: tipo 14.(C02;G01) | E26: 1000
D27: tipo 14.(C01;G03) | E27: 1000
D28: tipo 14.(C02;G03) | E28: 1000
D29: tipo 14.(C03;G01) | E29: 1000
D30: tipo 14.(C03;G03) | E30: 1000
B31: 8 | C31: COBRE BUS BAR TIPO 13 y TIPO 14 (C01;G02), (C01;G04), (C02;G02), (C02;G04), (C03;G02), (C03;G04) | D31: tipo 13 | E31: 1250 | F31: 160 | G31: 160 | J31: =SUM(E31:G31) -> 1570 | L31: =+Barras!E22 -> 1720
D32: tipo 14 (C01;G02) | E32: 1250 | F32: 160 | G32: 160
D33: tipo 14.(C01;G04) | E33: 1250 | F33: 160 | G33: 160 | K33: =+Barras!A22 -> 50 x 10
D34: tipo 14.(C02;G02) | E34: 1250 | F34: 160 | G34: 160 | K34: doble barra
D35: tipo 14.(C02;G04) | E35: 1250 | F35: 160 | G35: 160
D36: tipo 14.(C03;G02) | E36: 1250 | F36: 160 | G36: 160
D37: tipo 14.(C03;G04) | E37: 1250 | F37: 160 | G37: 160

Sheet Barras
A1: Ancho x Espesor | B1: Área | C1: Peso (i) | D1: Corriente alterna hasta 60 Hz | L1: Corriente Continua y Alterna 16 2/3 Hz | T1: Precio
D2: Pintado | H2: Brillante | L2: Pintado | P2: Brillante
D3: Número de Barras | H3: Número de Barras | L3: Número de Barras | P3: Número de Barras
D4: 1 | E4: 2 | F4: 3 | G4: 4 | H4: 1 | I4: 2 | J4: 3 | K4: 4 | L4: 1 | M4: 2 | N4: 3 | O4: 4 | P4: 1 | Q4: 2 | R4: 3 | S4: 4
A5: mm | B5: mm2 | C5: kg/m
A6: 12 x 2 | B6: 23.5 | C6: 0.209 | D6: 123 | E6: 202 | F6: 228 | H6: 108 | I6: 182 | J6: 216 | L6: 123 | M6: 202 | N6: 233 | P6: 108 | Q6: 182 | R6: 220 | T6: =70.08/6 -> 11.68
A7: 15 x 2 | B7: 29.5 | C7: 0.262 | D7: 148 | E7: 240 | F7: 261 | H7: 128 | I7: 212 | J7: 247 | L7: 148 | M7: 240 | N7: 267 | P7: 128 | Q7: 212 | R7: 252
A8: 15 x 3 | B8: 44.5 | C8: 0.396 | D8: 187 | E8: 316 | F8: 381 | H8: 162 | I8: 282 | J8: 361 | L8: 187 | M8: 316 | N8: 387 | P8: 162 | Q8: 282 | R8: 365 | T8: =111/6 -> 18.5
A9: 20 x 2 | B9: 39.5 | C9: 0.351 | D9: 189 | E9: 302 | F9: 313 | H9: 162 | I9: 264 | J9: 298 | L9: 189 | M9: 302 | N9: 321 | P9: 162 | Q9: 266 | R9: 303
A10: 20 x 3 | B10: 59.5 | C10: 0.529 | D10: 237 | E10: 394 | F10: 454 | H10: 204 | I10: 348 | J10: 431 | L10: 237 | M10: 394 | N10: 463 | P10: 204 | Q10: 348 | R10: 437 | T10: =149.41/6 -> 24.901667
A11: 20 x 5 | B11: 99.1 | C11: 0.882 | D11: 319 | E11: 560 | F11: 728 | H11: 274 | I11: 500 | J11: 690 | L11: 320 | M11: 562 | N11: 729 | P11: 274 | Q11: 502 | R11: 687 | T11: =246.98/6 -> 41.163333
A12: 20 x 10 | B12: 199 | C12: 1.77 | D12: 497 | E12: 924 | F12: 1320 | H12: 427 | I12: 825 | J12: 1180 | L12: 499 | M12: 932 | N12: 1300 | P12: 428 | Q12: 832 | R12: 1210 | T12: =+T11*2 -> 82.326667
A13: 25 x 3 | B13: 74.5 | C13: 0.663 | D13: 287 | E13: 470 | F13: 525 | H13: 245 | I13: 412 | J13: 498 | L13: 287 | M13: 470 | N13: 536 | P13: 245 | Q13: 414 | R13: 506 | T13: =188.7/6 -> 31.45
A14: 25 x 5 | B14: 124 | C14: 1.11 | D14: 384 | E14: 662 | F14: 869 | H14: 327 | I14: 586 | J14: 795 | L14: 384 | M14: 664 | N14: 841 | P14: 327 | Q14: 590 | R14: 794 | T14: =312.21/6 -> 52.035
A15: 30 x 3 | B15: 89.5 | C15: 0.796 | D15: 337 | E15: 544 | F15: 593 | H15: 285 | I15: 476 | J15: 564 | L15: 337 | M15: 546 | N15: 608 | P15: 286 | Q15: 478 | R15: 575 | T15: =222/6 -> 37
A16: 30 x 5 | B16: 149 | C16: 1.33 | D16: 447 | E16: 760 | F16: 944 | H16: 379 | I16: 672 | J16: 896 | L16: 448 | M16: 766 | N16: 950 | P16: 380 | Q16: 676 | R16: 897 | T16: =373.26/6 -> 62.21 | U16: =+T16*2 -> 124.42
A17: 30 x 10 | B17: 299 | C17: 2.66 | D17: 676 | E17: 1200 | F17: 1670 | H17: 573 | I17: 1060 | J17: 1480 | L17: 683 | M17: 1230 | N17: 1630 | P17: 579 | Q17: 1080 | R17: 1520 | T17: =743.7/6 -> 123.95
A18: 40 x 3 | B18: 119 | C18: 1.06 | D18: 435 | E18: 692 | F18: 725 | H18: 366 | I18: 600 | J18: 690 | L18: 436 | M18: 696 | N18: 748 | P18: 367 | Q18: 604 | R18: 708 | T18: =298.7/6 -> 49.783333 | V18: =800*1.25 -> 1000
A19: 40 x 5 | B19: 199 | C19: 1.77 | D19: 573 | E19: 952 | F19: 1140 | H19: 482 | I19: 836 | J19: 1090 | L19: 576 | M19: 986 | N19: 1180 | P19: 484 | Q19: 848 | R19: 1100 | T19: =494.88/6 -> 82.48
A20: 40 x 10 | B20: 399 | C20: 3.55 | D20: 850 | E20: 1470 | F20: 2000 | G20: 2580 | H20: 715 | I20: 1290 | J20: 1770 | K20: 2280 | L20: 865 | M20: 1530 | N20: 2000 | P20: 728 | Q20: 1350 | R20: 1880 | T20: =994.38/6 -> 165.73
A21: 50 x 5 | B21: 249 | C21: 2.22 | D21: 697 | E21: 1140 | F21: 1330 | G21: 2010 | H21: 583 | I21: 994 | J21: 1260 | K21: 1920 | L21: 703 | M21: 1170 | N21: 1370 | P21: 588 | Q21: 1020 | R21: 1300 | T21: =624.38/6 -> 104.06333
A22: 50 x 10 | B22: 499 | C22: 4.44 | D22: 1020 | E22: 1720 | F22: 2320 | G22: 2950 | H22: 852 | I22: 1510 | J22: 2040 | K22: 2500 | L22: 1050 | M22: 1830 | N22: 2360 | P22: 875 | Q22: 1610 | R22: 2220 | T22: =1237.21/6 -> 206.20167
A23: 60 x 5 | B23: 299 | C23: 2.66 | D23: 826 | E23: 1330 | F23: 1510 | G23: 2310 | H23: 888 | I23: 1150 | J23: 1440 | K23: 2210 | L23: 836 | M23: 1370 | N23: 1580 | O23: 2080 | P23: 696 | Q23: 1190 | R23: 1500 | S23: 1970 | T23: =740.93/6 -> 123.48833
A24: 60 x 10 | B24: 599 | C24: 5.33 | D24: 1180 | E24: 1960 | F24: 2610 | G24: 3290 | H24: 985 | I24: 1720 | J24: 2300 | K24: 2900 | L24: 1230 | M24: 2130 | N24: 2720 | O24: 3580 | P24: 1020 | Q24: 1870 | R24: 2570 | S24: 3390 | T24: =1493.88/6 -> 248.98
A25: 80 x 5 | B25: 399 | C25: 3.55 | D25: 1070 | E25: 1880 | F25: 1830 | G25: 2830 | H25: 885 | I25: 1450 | J25: 1750 | K25: 2720 | L25: 1090 | M25: 1770 | N25: 1990 | O25: 2570 | P25: 902 | Q25: 1530 | R25: 1890 | S25: 2480 | T25: =631.3/6 -> 105.21667
A26: 80 x 10 | B26: 799 | C26: 7.11 | D26: 1500 | E26: 2410 | F26: 3170 | G26: 3930 | H26: 1240 | I26: 2110 | J26: 2790 | K26: 3450 | L26: 1590 | M26: 2730 | N26: 3420 | O26: 4490 | P26: 1310 | Q26: 2380 | R26: 3240 | S26: 4280 | T26: =1977.21/6 -> 329.535
A27: 100 x 5 | B27: 499 | C27: 4.44 | D27: 1300 | E27: 2010 | F27: 2150 | G27: 3300 | H27: 1080 | I27: 1730 | J27: 2050 | K27: 3190 | L27: 1340 | M27: 2160 | N27: 2380 | O27: 3080 | P27: 1110 | Q27: 1810 | R27: 2270 | S27: 2960
A28: 100 x 10 | B28: 999 | C28: 8.89 | D28: 1810 | E28: 2850 | F28: 3720 | G28: 4530 | H28: 1490 | I28: 2480 | J28: 3280 | K28: 3980 | L28: 1940 | M28: 3310 | N28: 4100 | O28: 5310 | P28: 1600 | Q28: 2890 | R28: 3900 | S28: 5150 | T28: =2474.38/6 -> 412.39667
A29: 120 x 10 | B29: 1200 | C29: 10.7 | D29: 2110 | E29: 3280 | F29: 4270 | G29: 5130 | H29: 1740 | I29: 2860 | J29: 3740 | K29: 4500 | L29: 2300 | M29: 3900 | N29: 4780 | O29: 6260 | P29: 1890 | Q29: 3390 | R29: 4580 | S29: 6010
A30: 160 x 10 | B30: 1600 | C30: 14.2 | D30: 2700 | E30: 4130 | F30: 5360 | G30: 6320 | H30: 2220 | I30: 3590 | J30: 4680 | K30: 5530 | L30: 3010 | M30: 5060 | N30: 6130 | O30: 8010 | P30: 2470 | Q30: 4400 | R30: 5860 | S30: 7110 | T30: =3718.5/6 -> 619.75
